<?xml version="1.0" encoding="utf-8"?>
<!-- =================================================================================== -->
<!-- |    This document was autogenerated by xacro from wx200.urdf.xacro               | -->
<!-- |    EDITING THIS FILE BY HAND IS NOT RECOMMENDED                                 | -->
<!-- =================================================================================== -->
<robot name="wx200">
  <material name="black">
    <color rgba="0.0 0.0 0.0 1.0"/>
  </material>
  <material name="blue">
    <color rgba="0.0 0.0 0.8 1.0"/>
  </material>
  <material name="green">
    <color rgba="0.0 0.8 0.0 1.0"/>
  </material>
  <material name="grey">
    <color rgba="0.2 0.2 0.2 1.0"/>
  </material>
  <material name="silver">
    <color rgba="0.913725490196 0.913725490196 0.847058823529 1.0"/>
  </material>
  <material name="orange">
    <color rgba="1.0 0.423529411765 0.0392156862745 1.0"/>
  </material>
  <material name="brown">
    <color rgba="0.870588235294 0.811764705882 0.764705882353 1.0"/>
  </material>
  <material name="red">
    <color rgba="0.8 0.0 0.0 1.0"/>
  </material>
  <material name="white">
    <color rgba="1.0 1.0 1.0 1.0"/>
  </material>

  <link name="world">
    <visual>
      <origin rpy="0 0 0" xyz="0 0 0"/>
      <geometry>
        <box size="0 0 0"/>
      </geometry>
    </visual>
  </link>

  <joint name="base_static_joint" type="fixed">
    <origin rpy="0 -1.57 0" xyz="0. 0 0"/>
    <parent link="world"/>
    <child link="wx200/base_link"/>
  </joint>

  <link name="wx200/base_link">
    <visual>
      <origin rpy="0 0 1.57079632679" xyz="0 0 0"/>
      <geometry>
        <mesh filename="../meshes/wx200_1_base.dae" scale="0.001 0.001 0.001"/>
      </geometry>
      <material name="orange"/>
    </visual>
    <collision>
      <!-- <origin rpy="0 0 1.57079632679" xyz="0 0 0"/> -->
      <origin rpy="1.57079632679 0 1.57079632679" xyz="0 0 0"/>
      <geometry>
        <mesh filename="../meshes/wx200_1_base.dae" scale="0.001 0.001 0.001"/>
      </geometry>
    </collision>
    <inertial>
      <origin rpy="0 0 1.57079632679" xyz="-0.0381747000 0.0006478630 0.0193458000"/>
      <mass value="0.540142"/>
      <inertia ixx="0.0021190000" ixy="-0.0000172100" ixz="0.0000006389" iyy="0.0006925000" iyz="0.0000461200" izz="0.0025280000"/>
    </inertial>
  </link>

  <joint name="waist" type="revolute">
    <axis xyz="1 0 0"/>
    <limit effort="8" lower="-3.14158265359" upper="3.14158265359" velocity="3.14159265359"/>
    <!-- <origin rpy="0 0 0" xyz="0 0 0.072"/> -->
    <origin rpy="0 0 0" xyz="0.072 0 0"/>
    <parent link="wx200/base_link"/>
    <child link="wx200/shoulder_link"/>
    <dynamics friction="0."/>
  </joint>

  <link name="wx200/shoulder_link">
    <visual>
      <origin rpy="0 0 1.57079632679" xyz="0 0 -0.003"/>
      <geometry>
        <mesh filename="../meshes/wx200_2_shoulder.dae" scale="0.001 0.001 0.001"/>
      </geometry>
      <material name="red"/>
    </visual>
    <collision>
      <!-- <origin rpy="0 0 1.57079632679" xyz="0 0 -0.003"/> -->
      <origin rpy="1.57079632679 0 1.57079632679" xyz="0 0 -0.003"/>
      <geometry>
        <mesh filename="../meshes/wx200_2_shoulder.dae" scale="0.001 0.001 0.001"/>
      </geometry>
    </collision>
    <inertial>
      <origin rpy="0 0 1.57079632679" xyz="0.0000223210 0.0000414608 0.0066287000"/>
      <mass value="0.480879"/>
      <inertia ixx="0.0003790000" ixy="0.0000000022" ixz="-0.0000003561" iyy="0.0005557000" iyz="0.0000012247" izz="0.0005889000"/>
    </inertial>
  </link>

  <joint name="shoulder" type="revolute">
    <!-- <axis xyz="0 1 0"/> -->
    <axis xyz="0 1 0"/>
    <limit effort="18" lower="-1.88495559215" upper="1.97222205475" velocity="3.14159265359"/>
    <!-- <origin rpy="0 0 0" xyz="0 0 0.03865"/> -->
    <origin rpy="0 0 0" xyz="0.03865 0 0"/>
    <parent link="wx200/shoulder_link"/>
    <child link="wx200/upper_arm_link"/>
    <dynamics friction="0."/>
  </joint>
 
  <link name="wx200/upper_arm_link">
    <visual>
      <origin rpy="0 0 1.57079632679" xyz="0 0 0"/>
      <geometry>
        <mesh filename="../meshes/wx200_3_upper_arm.dae" scale="0.001 0.001 0.001"/>
      </geometry>
      <material name="black"/>
    </visual>
    <collision>
      <!-- <origin rpy="0 0 1.57079632679" xyz="0 0 0"/> -->
      <origin rpy="1.57079632679 0 1.57079632679" xyz="0 0 0"/>
      <geometry>
        <mesh filename="../meshes/wx200_3_upper_arm.dae" scale="0.001 0.001 0.001"/>
      </geometry>
    </collision>
    <inertial>
      <origin rpy="0 0 1.57079632679" xyz="0.0119707000 -0.0001179264 0.1394290000"/>
      <mass value="0.297781"/>
      <inertia ixx="0.0017100000" ixy="-0.0000011433" ixz="0.0000021161" iyy="0.0016310000" iyz="0.0002135000" izz="0.0001482000"/>
    </inertial>
  </link>

  <joint name="elbow" type="revolute">
    <!-- <axis xyz="0 1 0"/> -->
    <axis xyz="0 1 0"/>
    <limit effort="13" lower="-1.88495559215" upper="1.62315620435" velocity="3.14159265359"/>
    <!-- <origin rpy="0 0 0" xyz="0.05 0 0.2"/> -->
    <origin rpy="0 0 0" xyz="0.2 0 -0.05"/>
    <parent link="wx200/upper_arm_link"/>
    <child link="wx200/forearm_link"/>
    <dynamics friction="0."/>
  </joint>
 
  <link name="wx200/forearm_link">
    <visual>
      <origin rpy="0 0 1.57079632679" xyz="0 0 0"/>
      <geometry>
        <mesh filename="../meshes/wx200_4_forearm.dae" scale="0.001 0.001 0.001"/>
      </geometry>
      <material name="red"/>
    </visual>
    <collision>
      <!-- <origin rpy="0 0 1.57079632679" xyz="0 0 0"/> -->
      <origin rpy="1.57079632679 0 1.57079632679" xyz="0 0 0"/>
      <geometry>
        <mesh filename="../meshes/wx200_4_forearm.dae" scale="0.001 0.001 0.001"/>
      </geometry>
    </collision>
    <inertial>
      <origin rpy="0 0 1.57079632679" xyz="0.1211920000 -0.0001238123 0.0000000000"/>
      <mass value="0.283651"/>
      <inertia ixx="0.0011850000" ixy="-0.0000024317" ixz="0.0000000000" iyy="0.0000682900" iyz="0.0000000000" izz="0.0012060000"/>
    </inertial>
  </link>

  <joint name="wrist_angle" type="revolute">
    <axis xyz="0 1 0"/>
    <limit effort="5" lower="-1.74532925199" upper="2.14675497995" velocity="3.14159265359"/>
    <!-- <origin rpy="0 0 0" xyz="0.2 0 0"/> -->
    <origin rpy="0 0 0" xyz="0 0 -0.2"/>
    <parent link="wx200/forearm_link"/>
    <child link="wx200/wrist_link"/>
    <dynamics friction="0."/>
  </joint>
 
  <link name="wx200/wrist_link">
    <visual>
      <origin rpy="0 0 1.57079632679" xyz="0 0 0"/>
      <geometry>
        <mesh filename="../meshes/wx200_5_wrist.dae" scale="0.001 0.001 0.001"/>
      </geometry>
      <material name="orange"/>
    </visual>
    <collision>
      <!-- <origin rpy="0 0 1.57079632679" xyz="0 0 0"/> -->
      <origin rpy="1.57079632679 0 1.57079632679" xyz="0 0 0"/>
      <geometry>
        <mesh filename="../meshes/wx200_5_wrist.dae" scale="0.001 0.001 0.001"/>
      </geometry>
    </collision>
    <inertial>
      <origin rpy="0 0 1.57079632679" xyz="0.0423600000 -0.0000106630 0.0105770000"/>
      <mass value="0.084957"/>
      <inertia ixx="0.0000308200" ixy="0.0000000191" ixz="0.0000000023" iyy="0.0000282200" iyz="0.0000025481" izz="0.0000315200"/>
    </inertial>
  </link>

  <joint name="wrist_rotate" type="revolute">
    <!-- <axis xyz="1 0 0"/> -->
    <axis xyz="0 0 -1"/>
    <limit effort="1" lower="-3.14158265359" upper="3.14158265359" velocity="3.14159265359"/>
    <!-- <origin rpy="0 0 0" xyz="0.065 0 0"/> -->
    <origin rpy="0 0 0" xyz="0.0 0 -0.045"/>
    <parent link="wx200/wrist_link"/>
    <child link="wx200/gripper_link"/>
    <dynamics friction="0."/>
  </joint>
 
  <link name="wx200/gripper_link">
    <visual>
      <!-- <origin rpy="0 0 1.57079632679" xyz="-0.02 0 0"/> -->
      <origin rpy="0 0 1.57079632679" xyz="0 0 0"/>
      <geometry>
        <mesh filename="../meshes/wx200_6_gripper.dae" scale="0.001 0.001 0.001"/>
      </geometry>
      <material name="green"/>
    </visual>
    <collision>
      <!-- <origin rpy="0 0 1.57079632679" xyz="-0.02 0 0"/> -->
      <origin rpy="1.57079632679 0 1.57079632679" xyz="0 0 0"/>
      <geometry>
        <mesh filename="../meshes/wx200_6_gripper.dae" scale="0.001 0.001 0.001"/>
      </geometry>
    </collision>
    <inertial>
      <origin rpy="0 0 1.57079632679" xyz="0.0216310000 0.0000002516 0.0114100000"/>
      <mass value="0.072885"/>
      <inertia ixx="0.0000253700" ixy="0.0000000000" ixz="0.0000000000" iyy="0.0000183600" iyz="0.0000004340" izz="0.0000167400"/>
    </inertial>
  </link>

  <!-- <joint name="ee_arm" type="fixed">
    <axis xyz="1 0 0"/>
    <axis xyz="0 0 1"/>
    <origin rpy="0 0 0" xyz="0.043 0 0"/>
    <origin rpy="0 0 0" xyz="0.0 0 -0.043"/>
    <parent link="wx200/gripper_link"/>
    <child link="wx200/ee_arm_link"/>
  </joint>

  <link name="wx200/ee_arm_link">
    <inertial>
      <mass value="0.001"/>
      <inertia ixx="0.001" ixy="0" ixz="0" iyy="0.001" iyz="0" izz="0.001"/>
    </inertial>
  </link> -->

  <joint name="gripper" type="fixed">
    <!-- <axis xyz="1 0 0"/> -->
    <axis xyz="0 0 1"/>
    <limit effort="1" velocity="3.14159265359"/>
    <!-- <origin rpy="0 0 0" xyz="0.0055 0 0"/> -->
    <origin rpy="0 0 0" xyz="0.083 0 0.0"/>
    <!-- <parent link="wx200/ee_arm_link"/> -->
    <parent link="wx200/gripper_link"/>
    <child link="wx200/gripper_prop_link"/>
    <dynamics friction="0."/>
  </joint>
 
  <link name="wx200/gripper_prop_link">
    <visual>
      <origin rpy="0 0 1.57079632679" xyz="-0.0685 0 0"/>
      <geometry>
        <mesh filename="../meshes/wx200_7_gripper_prop.dae" scale="0.001 0.001 0.001"/>
      </geometry>
      <material name="blue"/>
    </visual>
    <collision>
      <!-- <origin rpy="0 0 1.57079632679" xyz="-0.0685 0 0"/> -->
      <origin rpy="1.57079632679 0 1.57079632679" xyz="-0.0685 0 0"/>
      <geometry>
        <mesh filename="../meshes/wx200_7_gripper_prop.dae" scale="0.001 0.001 0.001"/>
      </geometry>
    </collision>
    <inertial>
      <origin rpy="0 0 1.57079632679" xyz="0.0008460000 -0.0000016817 0.0000420000"/>
      <mass value="0.00434"/>
      <inertia ixx="0.0000005923" ixy="0.0000000000" ixz="0.0000003195" iyy="0.0000011156" iyz="-0.0000000004" izz="0.0000005743"/>
    </inertial>
  </link>
  <!-- If the AR tag is being used, then add the AR tag mount -->
  <!-- If the gripper bar is being used, then also add the gripper bar -->
  <joint name="gripper_bar" type="fixed">
    <!-- <axis xyz="1 0 0"/> -->
    <axis xyz="0 0 1"/>
    <!-- <origin rpy="0 0 0" xyz="0 0 0"/> -->
    <origin rpy="0 0 0" xyz="0.063 0 0.0"/>
    <!-- <parent link="wx200/ee_arm_link"/> -->
    <parent link="wx200/gripper_link"/>
    <child link="wx200/gripper_bar_link"/>
  </joint>

  <link name="wx200/gripper_bar_link">
    <visual>
      <origin rpy="0 0 1.57079632679" xyz="-0.063 0 0"/>
      <geometry>
        <mesh filename="../meshes/wx200_8_gripper_bar.dae" scale="0.001 0.001 0.001"/>
      </geometry>
      <material name="black"/>
    </visual>
    <collision>
      <!-- <origin rpy="0 0 1.57079632679" xyz="-0.063 0 0"/> -->
      <origin rpy="1.57079632679 0 1.57079632679" xyz="-0.063 0 0"/>
      <geometry>
        <mesh filename="../meshes/wx200_8_gripper_bar.dae" scale="0.001 0.001 0.001"/>
      </geometry>
    </collision>
    <inertial>
      <origin rpy="0 0 1.57079632679" xyz="0.0096870000 0.0000008177 0.0049620000"/>
      <mass value="0.034199"/>
      <inertia ixx="0.0000074125" ixy="-0.0000000008" ixz="-0.0000000006" iyy="0.0000284300" iyz="-0.0000013889" izz="0.0000286000"/>
    </inertial>
  </link>
  <!-- <joint name="ee_bar" type="fixed">
    <axis xyz="1 0 0"/>
    <origin rpy="0 0 0" xyz="0.023 0 0"/>
    <parent link="wx200/gripper_bar_link"/>
    <child link="wx200/fingers_link"/>
  </joint>
  <link name="wx200/fingers_link">
   <visual>
      <origin rpy="0 0 1.57079632679" xyz="0 0 0"/>
    </visual>
    <inertial>
      <mass value="0.001"/>
      <inertia ixx="0.001" ixy="0" ixz="0" iyy="0.001" iyz="0" izz="0.001"/>
    </inertial>
  </link> -->
  <!-- If the gripper fingers are being used, add those as well -->
  <joint name="left_finger" type="prismatic">
    <axis xyz="0 1 0"/>
    <limit effort="5" lower="0.015" upper="0.037" velocity="1"/>
    <!-- <origin rpy="0 0 0" xyz="0 0 0"/> -->
    <origin rpy="0 0 0" xyz="-0.063 -0.005 -0.086"/>
    <!-- <parent link="wx200/fingers_link"/> -->
    <parent link="wx200/gripper_bar_link"/>
    <child link="wx200/left_finger_link"/>
    <dynamics friction="0."/>
  </joint>
 
  <link name="wx200/left_finger_link">
    <visual>
      <!-- <origin rpy="3.14159265359 3.14159265359 0" xyz="0 0.005 0"/> -->
      <origin rpy="1.57079632679 -1.57079632679 0" xyz="0 0.005 0"/>
      <geometry>
        <mesh filename="../meshes/wx200_9_gripper_finger.dae" scale="0.001 0.001 0.001"/>
      </geometry>
      <material name="blue"/>
    </visual>
    <collision>
      <!-- <origin rpy="3.14159265359 3.14159265359 0" xyz="0 0.005 0"/> -->
      <origin rpy="3.14159265359 -1.57079632679 0" xyz="0 0.005 0"/>
      <geometry>
        <mesh filename="../meshes/wx200_9_gripper_finger.dae" scale="0.001 0.001 0.001"/>
      </geometry>
    </collision>
    <inertial>
      <origin rpy="3.14159265359 3.14159265359 1.57079632679" xyz="0.0138160000 0.0000000000 0.0000000000"/>
      <mass value="0.016246"/>
      <inertia ixx="0.0000047310" ixy="-0.0000004560" ixz="0.0000000000" iyy="0.0000015506" iyz="0.0000000000" izz="0.0000037467"/>
    </inertial>
  </link>

  <joint name="right_finger" type="prismatic">
    <axis xyz="0 1 0"/>
    <limit effort="5" lower="-0.037" upper="-0.015" velocity="1"/>
    <!-- <origin rpy="0 0 0" xyz="0 0 0"/> -->
    <origin rpy="0 0 0" xyz="-0.063 -0.005 -0.086"/>
    <!-- <parent link="wx200/fingers_link"/> -->
    <parent link="wx200/gripper_bar_link"/>
    <child link="wx200/right_finger_link"/>
    <dynamics friction="0."/>
    <mimic joint="left_finger" multiplier="-1" offset="0"/>
  </joint>
  
  <link name="wx200/right_finger_link">
    <visual>
      <!-- <origin rpy="0 3.14159265359 0" xyz="0 -0.005 0"/> -->
      <origin rpy="-1.57079632679 -1.57079632679 0" xyz="0 0.005 0"/>
      <geometry>
        <mesh filename="../meshes/wx200_9_gripper_finger.dae" scale="0.001 0.001 0.001"/>
      </geometry>
      <material name="red"/>
    </visual>
    <collision>
      <!-- <origin rpy="0 3.14159265359 0" xyz="0 -0.005 0"/> -->
      <origin rpy="0 -1.57079632679 0" xyz="0 0.005 0"/>
      <geometry>
        <mesh filename="../meshes/wx200_9_gripper_finger.dae" scale="0.001 0.001 0.001"/>
      </geometry>
    </collision>
    <inertial>
      <origin rpy="0 3.14159265359 1.57079632679" xyz="0.0138160000 0.0000000000  0.0000000000"/>
      <mass value="0.016246"/>
      <inertia ixx="0.0000047310" ixy="0.0000004560" ixz="0.0000000000" iyy="0.0000015506" iyz="0.0000000000" izz="0.0000037467"/>
    </inertial>
  </link>
  <joint name="ee_gripper" type="fixed"  dont_collapse="true">
    <!-- <axis xyz="1 0 0"/> -->
    <axis xyz="0 0 1"/>
    <!-- <origin rpy="0 0 0" xyz="0.027575 0 0"/> -->
    <origin rpy="0 0 0" xyz="-0.04 0.0 -0.08"/>
    <!-- <parent link="wx200/fingers_link"/> -->
    <parent link="wx200/gripper_bar_link"/>
    <child link="wx200/ee_gripper_link"/>
  </joint>
  <link name="wx200/ee_gripper_link">
    <inertial>
      <mass value="0.001"/>
      <inertia ixx="0.001" ixy="0" ixz="0" iyy="0.001" iyz="0" izz="0.001"/>
    </inertial>
  </link>
</robot>

